<mujoco model="r15">

  <statistic extent="2" center="0 0 1"/>

  <option timestep="0.00555"/>

  <default>
    <motor ctrlrange="-1 1" ctrllimited="true"/>
    <default class="body">
      <geom type="capsule" condim="1" friction="1.0 0.05 0.05" solimp=".9 .99 .003" solref=".015 1"/>
      <joint type="hinge" damping="0.1" stiffness="5" armature=".007" limited="true" solimplimit="0 .99 .01"/>
      <site size=".04" group="3"/>
      <default class="force-torque">
        <site type="box" size=".01 .01 .02" rgba="1 0 0 1" />
      </default>
      <default class="touch">
        <site type="capsule" rgba="0 0 1 .3"/>
      </default>
    </default>
  </default>

  <worldbody>
    <light diffuse="1 1 1" pos="0 0 10" dir="0 0 -1"/>
<body name="LowerTorso" pos="0 0.669872007369995 0">
  <inertial pos="0 0 0" mass="12.3093695831299" diaginertia="0.0939753290435791 0.399994085021972 0.331837694203186"/>
  <freejoint name="root"/>
  <geom name="LowerTorso" type="box" size="0.278797702789306 0.0560914748907089 0.140559992790223"/>
  <body name="RightUpperLeg" pos="0.14 -0.187982840538024 1.28173828125e-05">
    <inertial pos="0 0 0" mass="20.2258494644165" diaginertia="0.370491357885743 0.255283778773499 0.375722849510193"/>
    <joint name="RightHip_x" pos="0 0.131990195512772 -1.81762027204968e-05" type="hinge" axis="1 0 0"/>
    <joint name="RightHip_y" pos="0 0.131990195512772 -1.81762027204968e-05" type="hinge" axis="0 1 0"/>
    <joint name="RightHip_z" pos="0 0.131990195512772 -1.81762027204968e-05" type="hinge" axis="0 0 1"/>
    <geom name="RightUpperLeg" type="box" size="0.138998091220856 0.190810475349427 0.136178233623505"/>
    <body name="RightLowerLeg" pos="0 -0.241509082317353 -1.28841400146484e-05">
      <inertial pos="0 0 0" mass="19.3037530326843" diaginertia="0.332707459530639 0.243669545773315 0.337676290489196"/>
      <joint name="RightKnee_x" pos="0 0.11574049949646 6.96039380272849e-06" type="hinge" axis="1 0 0"/>
      <geom name="RightLowerLeg" type="box" size="0.138998091220856 0.182093019485474 0.136192002296448"/>
      <body name="RightFoot" pos="0 -0.196700855493545 -6.67572021484376e-07">
        <inertial pos="0 0 0" mass="4.8419257736206" diaginertia="0.0347806883102417 0.0638992851219178 0.0352770976064683"/>
        <joint name="RightAnkle_x" pos="0 0.0296842887997628 2.14282164233737e-05" type="hinge" axis="1 0 0"/>
        <joint name="RightAnkle_y" pos="0 0.0296842887997628 2.14282164233737e-05" type="hinge" axis="0 1 0"/>
        <joint name="RightAnkle_z" pos="0 0.0296842887997628 2.14282164233737e-05" type="hinge" axis="0 0 1"/>
        <geom name="RightFoot" type="box" size="0.141242368221283 0.0436791372299194 0.140149335861206"/>
      </body>
    </body>
  </body>
  <body name="LeftUpperLeg" pos="-0.14 -0.187982773780822 6.67572021484374e-08">
    <inertial pos="0 0 0" mass="20.2258494644165" diaginertia="0.370491357885743 0.255283778773499 0.375722849510193"/>
    <joint name="LeftHip_x" pos="1.65698637033529e-08 0.131990162134171 -4.46472165549494e-08" type="hinge" axis="1 0 0"/>
    <joint name="LeftHip_y" pos="1.65698637033529e-08 0.131990162134171 -4.46472165549494e-08" type="hinge" axis="0 1 0"/>
    <joint name="LeftHip_z" pos="1.65698637033529e-08 0.131990162134171 -4.46472165549494e-08" type="hinge" axis="0 0 1"/>
    <geom name="LeftUpperLeg" type="box" size="0.138998091220856 0.190810475349427 0.136178233623505"/>
    <body name="LeftLowerLeg" pos="0 -0.241510434150697 -6.67572021484374e-08">
      <inertial pos="0 0 0" mass="19.3037530326843" diaginertia="0.332707459530639 0.243669545773315 0.337676290489196"/>
      <joint name="LeftKnee_x" pos="8.28493185167645e-09 0.115692926645279 -4.38158519955324e-08" type="hinge" axis="1 0 0"/>
      <geom name="LeftLowerLeg" type="box" size="0.138998091220856 0.182093019485474 0.136192002296448"/>
      <body name="LeftFoot" pos="0 -0.196700884699821 -1.33514404296875e-07">
        <inertial pos="0 0 0" mass="4.8419257736206" diaginertia="0.0347806883102417 0.0638992851219178 0.0352770976064683"/>
        <joint name="LeftAnkle_x" pos="-5.05122090999067e-08 0.0296843221783637 -4.82752138850629e-07" type="hinge" axis="1 0 0"/>
        <joint name="LeftAnkle_y" pos="-5.05122090999067e-08 0.0296843221783637 -4.82752138850629e-07" type="hinge" axis="0 1 0"/>
        <joint name="LeftAnkle_z" pos="-5.05122090999067e-08 0.0296843221783637 -4.82752138850629e-07" type="hinge" axis="0 0 1"/>
        <geom name="LeftFoot" type="box" size="0.141242368221283 0.0436791372299194 0.140149335861206"/>
      </body>
    </body>
  </body>
  <body name="UpperTorso" pos="0 0.293727684020996 -6.67572021484374e-08">
    <inertial pos="0 0 0" mass="50.9062170867921" diaginertia="1.29420598590698 1.59112148022461 2.21482100264893"/>
    <joint name="Waist_x" pos="-1.62153889959882e-08 -0.237720127105713 3.35121137595706e-08" type="hinge" axis="1 0 0"/>
    <joint name="Waist_y" pos="-1.62153889959882e-08 -0.237720127105713 3.35121137595706e-08" type="hinge" axis="0 1 0"/>
    <joint name="Waist_z" pos="-1.62153889959882e-08 -0.237720127105713 3.35121137595706e-08" type="hinge" axis="0 0 1"/>
    <geom name="UpperTorso" type="box" size="0.272049083709717 0.237724432945251 0.140559992790223"/>
    <body name="LeftUpperArm" pos="-0.412199554443359 0.0500051498413096 -6.67572021484377e-08">
      <inertial pos="0 0 0" mass="19.1349013175964" diaginertia="0.318200317552185 0.25076338409729 0.318000026612853"/>
      <joint name="LeftShoulder_x" pos="0.140149435997009 0.117298529148102 2.50806806434412e-08" type="hinge" axis="1 0 0"/>
      <joint name="LeftShoulder_y" pos="0.140149435997009 0.117298529148102 2.50806806434412e-08" type="hinge" axis="0 1 0"/>
      <joint name="LeftShoulder_z" pos="0.140149435997009 0.117298529148102 2.50806806434412e-08" type="hinge" axis="0 0 1"/>
      <geom name="LeftUpperArm" type="box" size="0.140149335861206 0.173823771476746 0.140261337757111"/>
      <body name="LeftLowerArm" pos="0 -0.176321258544922 6.67572021484377e-08">
        <inertial pos="0 0 0" mass="17.2225517539978" diaginertia="0.253460797834778 0.225701986724853 0.253280510343933"/>
        <joint name="LeftElbow_x" pos="0.000134158034343273 0.0769507765769957 2.14449078610665e-20" type="hinge" axis="1 0 0"/>
        <geom name="LeftLowerArm" type="box" size="0.140149335861206 0.156451745033265 0.140261337757111"/>
        <body name="LeftHand" pos="2.13623046837697e-06 -0.185849714279174 0">
          <inertial pos="0 0 0" mass="4.91083613586426" diaginertia="0.0371226305099488 0.0650060849025726 0.0342815317455293"/>
          <geom name="LeftHand" type="box" size="0.137797329425812 0.0442071783542633 0.143957333564758"/>
        </body>
      </body>
    </body>
    <body name="RightUpperArm" pos="0.412199554443359 0.0500051498413096 0">
      <inertial pos="0 0 0" mass="19.1349013175964" diaginertia="0.318200317552185 0.25076338409729 0.318000026612853"/>
      <joint name="RightShoulder_x" pos="-0.140149536132813 0.117298529148102 2.50806806434412e-08" type="hinge" axis="1 0 0"/>
      <joint name="RightShoulder_y" pos="-0.140149536132813 0.117298529148102 2.50806806434412e-08" type="hinge" axis="0 1 0"/>
      <joint name="RightShoulder_z" pos="-0.140149536132813 0.117298529148102 2.50806806434412e-08" type="hinge" axis="0 0 1"/>
      <geom name="RightUpperArm" type="box" size="0.140149335861206 0.173823771476746 0.140261337757111"/>
      <body name="RightLowerArm" pos="0 -0.176321258544922 0">
        <inertial pos="0 0 0" mass="17.2225517539978" diaginertia="0.253460797834778 0.225701986724853 0.253280510343933"/>
        <joint name="RightElbow_x" pos="3.34142055180564e-08 0.0769184410572052 2.14449078610665e-20" type="hinge" axis="1 0 0"/>
        <geom name="RightLowerArm" type="box" size="0.140149335861206 0.156451745033265 0.140261337757111"/>
        <body name="RightHand" pos="0 -0.185849714279174 0">
          <inertial pos="0 0 0" mass="4.91083613586426" diaginertia="0.0371226305099488 0.0650060849025726 0.0342815317455293"/>
          <geom name="RightHand" type="box" size="0.137797329425812 0.0442071783542633 0.143957333564758"/>
        </body>
      </body>
    </body>
    <body name="Head" pos="0 0.375294370651245 7.39002227783203e-05">
      <inertial pos="0 0 0" mass="24.4547679367065" diaginertia="0.438244884381104 0.430421535678101 0.438222931878662"/>
      <joint name="Neck_x" pos="0 -0.137564029693604 -7.38566741347313e-05" type="hinge" axis="1 0 0"/>
      <joint name="Neck_y" pos="0 -0.137564029693604 -7.38566741347313e-05" type="hinge" axis="0 1 0"/>
      <joint name="Neck_z" pos="0 -0.137564029693604 -7.38566741347313e-05" type="hinge" axis="0 0 1"/>
      <geom name="Head" type="box" size="0.16247995376587 0.165406973361969 0.162488231658935"/>
    </body>
  </body>
</body>
  </worldbody>
</mujoco>
